Workbook

Sheet 入院患者
A1: 患者情報 | E1: 臨床情報 | J1: 治療 | O1: その他
A2: ID | B2: イニシャル | C2: 年齢 | D2: 性別 | E2: 疾患 | F2: 病期/Stage | G2: 入院日 | H2: 退院日 | I2: 在院日数 | J2: PS | K2: 治療区分 | L2: 治療レジメン | M2: サイクル数 | N2: 転帰 | O2: ステータス | P2: 備考
I3: =IF(AND(G3<>"",H3<>""),H3-G3,"")
I4: =IF(AND(G4<>"",H4<>""),H4-G4,"")
I5: =IF(AND(G5<>"",H5<>""),H5-G5,"")
I6: =IF(AND(G6<>"",H6<>""),H6-G6,"")
I7: =IF(AND(G7<>"",H7<>""),H7-G7,"")
I8: =IF(AND(G8<>"",H8<>""),H8-G8,"")
I9: =IF(AND(G9<>"",H9<>""),H9-G9,"")
I10: =IF(AND(G10<>"",H10<>""),H10-G10,"")
I11: =IF(AND(G11<>"",H11<>""),H11-G11,"")
I12: =IF(AND(G12<>"",H12<>""),H12-G12,"")
I13: =IF(AND(G13<>"",H13<>""),H13-G13,"")
I14: =IF(AND(G14<>"",H14<>""),H14-G14,"")
... I102: =IF(AND(G102<>"",H102<>""),H102-G102,"")

Sheet 他科コンサルト
A1: 患者情報 | E1: コンサルト内容 | K1: 対応 | M1: その他
A2: ID | B2: イニシャル | C2: 年齢 | D2: 性別 | E2: 緊急度 | F2: コンサルト日 | G2: 依頼科 | H2: 依頼医 | I2: コンサルト理由 | J2: 疾患(疑い含む) | K2: 対応内容 | L2: フォロー要否 | M2: 備考

Sheet 初診外来
A1: 患者情報 | E1: 受診情報 | H1: 臨床情報 | K1: 治療 | O1: その他
A2: ID | B2: イニシャル | C2: 年齢 | D2: 性別 | E2: 初診日 | F2: 紹介元 | G2: 主訴 | H2: 疾患 | I2: 病期/Stage | J2: PS | K2: 治療区分 | L2: 治療レジメン | M2: 転帰 | N2: 次回予約日 | O2: 備考

Sheet サマリー
B2: 症例管理サマリー
B4: 入院患者 - 疾患別 | E4: 入院患者 - 治療区分別 | H4: 入院患者 - ステータス別
B5: 項目 | C5: 件数 | E5: 項目 | F5: 件数 | H5: 項目 | I5: 件数
B6: AML | C6: =COUNTIF('入院患者'!E3:E102,"AML") | E6: 化学療法 | F6: =COUNTIF('入院患者'!K3:K102,"化学療法") | H6: 入院中 | I6: =COUNTIF('入院患者'!O3:O102,"入院中")
B7: ALL | C7: =COUNTIF('入院患者'!E3:E102,"ALL") | E7: 自家移植 | F7: =COUNTIF('入院患者'!K3:K102,"自家移植") | H7: 退院済 | I7: =COUNTIF('入院患者'!O3:O102,"退院済")
B8: CML | C8: =COUNTIF('入院患者'!E3:E102,"CML") | E8: 同種移植 | F8: =COUNTIF('入院患者'!K3:K102,"同種移植") | H8: 外来移行 | I8: =COUNTIF('入院患者'!O3:O102,"外来移行")
B9: CLL | C9: =COUNTIF('入院患者'!E3:E102,"CLL") | E9: CAR-T | F9: =COUNTIF('入院患者'!K3:K102,"CAR-T") | H9: 合計 | I9: =COUNTA('入院患者'!A3:A102)
B10: MDS | C10: =COUNTIF('入院患者'!E3:E102,"MDS") | E10: 分子標的薬 | F10: =COUNTIF('入院患者'!K3:K102,"分子標的薬")
B11: MPN | C11: =COUNTIF('入院患者'!E3:E102,"MPN") | E11: 免疫療法 | F11: =COUNTIF('入院患者'!K3:K102,"免疫療法")
B12: CMML | C12: =COUNTIF('入院患者'!E3:E102,"CMML") | E12: 放射線 | F12: =COUNTIF('入院患者'!K3:K102,"放射線")
B13: DLBCL | C13: =COUNTIF('入院患者'!E3:E102,"DLBCL") | E13: BSC | F13: =COUNTIF('入院患者'!K3:K102,"BSC")
B14: FL | C14: =COUNTIF('入院患者'!E3:E102,"FL") | E14: 経過観察 | F14: =COUNTIF('入院患者'!K3:K102,"経過観察")
B15: MCL | C15: =COUNTIF('入院患者'!E3:E102,"MCL") | E15: 合計 | F15: =COUNTA('入院患者'!A3:A102)
B16: BL | C16: =COUNTIF('入院患者'!E3:E102,"BL")
B17: MALT | C17: =COUNTIF('入院患者'!E3:E102,"MALT")
B18: ATLL | C18: =COUNTIF('入院患者'!E3:E102,"ATLL")
B19: PTCL | C19: =COUNTIF('入院患者'!E3:E102,"PTCL")
B20: AITL | C20: =COUNTIF('入院患者'!E3:E102,"AITL")
B21: NK/T | C21: =COUNTIF('入院患者'!E3:E102,"NK/T")
B22: HL | C22: =COUNTIF('入院患者'!E3:E102,"HL")
B23: MM | C23: =COUNTIF('入院患者'!E3:E102,"MM")
B24: WM | C24: =COUNTIF('入院患者'!E3:E102,"WM")
B25: AL amyloidosis | C25: =COUNTIF('入院患者'!E3:E102,"AL amyloidosis")
B26: AA | C26: =COUNTIF('入院患者'!E3:E102,"AA")
B27: PNH | C27: =COUNTIF('入院患者'!E3:E102,"PNH")
B28: ITP | C28: =COUNTIF('入院患者'!E3:E102,"ITP")
B29: TTP | C29: =COUNTIF('入院患者'!E3:E102,"TTP")
B30: HUS | C30: =COUNTIF('入院患者'!E3:E102,"HUS")
B31: DIC | C31: =COUNTIF('入院患者'!E3:E102,"DIC")
B32: HLH | C32: =COUNTIF('入院患者'!E3:E102,"HLH")
B33: その他 | C33: =COUNTIF('入院患者'!E3:E102,"その他")
B34: 合計 | C34: =COUNTA('入院患者'!A3:A102)
B36: 入院患者 - 転帰別 | E36: 他科コンサルト - 疾患別 | H36: 他科コンサルト - 緊急度別
B37: 項目 | C37: 件数 | E37: 項目 | F37: 件数 | H37: 項目 | I37: 件数
B38: CR | C38: =COUNTIF('入院患者'!N3:N102,"CR") | E38: AML | F38: =COUNTIF('他科コンサルト'!J3:J102,"AML") | H38: 緊急 | I38: =COUNTIF('他科コンサルト'!E3:E102,"緊急")
B39: CRi | C39: =COUNTIF('入院患者'!N3:N102,"CRi") | E39: ALL | F39: =COUNTIF('他科コンサルト'!J3:J102,"ALL") | H39: 通常 | I39: =COUNTIF('他科コンサルト'!E3:E102,"通常")
B40: PR | C40: =COUNTIF('入院患者'!N3:N102,"PR") | E40: CML | F40: =COUNTIF('他科コンサルト'!J3:J102,"CML") | H40: 合計 | I40: =COUNTA('他科コンサルト'!A3:A102)
B41: VGPR | C41: =COUNTIF('入院患者'!N3:N102,"VGPR") | E41: CLL | F41: =COUNTIF('他科コンサルト'!J3:J102,"CLL")
B42: sCR | C42: =COUNTIF('入院患者'!N3:N102,"sCR") | E42: MDS | F42: =COUNTIF('他科コンサルト'!J3:J102,"MDS")
B43: SD | C43: =COUNTIF('入院患者'!N3:N102,"SD") | E43: MPN | F43: =COUNTIF('他科コンサルト'!J3:J102,"MPN")
...
